<?xml version="1.0" encoding="UTF-8"?>
<!-- Generated by org.testng.reporters.JUnitReportReporter -->
<testsuite skipped="4" hostname="DESKTOP-HBCBIO0" name="org.Failed.Testcase1" tests="7" failures="1" timestamp="04 Jun 2020 14:22:29 GMT" time="0.042" errors="0">
  <testcase name="test2" time="0.002" classname="org.Failed.Testcase1">
    <skipped/>
  </testcase> <!-- test2 -->
  <testcase name="test1" time="0.007" classname="org.Failed.Testcase1"/>
  <testcase name="test2" time="0.004" classname="org.Failed.Testcase1">
    <skipped/>
  </testcase> <!-- test2 -->
  <testcase name="test2" time="0.002" classname="org.Failed.Testcase1">
    <skipped/>
  </testcase> <!-- test2 -->
  <testcase name="test2" time="0.002" classname="org.Failed.Testcase1">
    <failure type="java.lang.AssertionError" message="expected [true] but found [false]">
      <![CDATA[java.lang.AssertionError: expected [true] but found [false]
at org.testng.Assert.fail(Assert.java:96)
at org.testng.Assert.failNotEquals(Assert.java:776)
at org.testng.Assert.assertTrue(Assert.java:44)
at org.testng.Assert.assertTrue(Assert.java:54)
at org.Failed.Testcase1.test2(Testcase1.java:16)
at sun.reflect.NativeMethodAccessorImpl.invoke0(Native Method)
at sun.reflect.NativeMethodAccessorImpl.invoke(Unknown Source)
at sun.reflect.DelegatingMethodAccessorImpl.invoke(Unknown Source)
at java.lang.reflect.Method.invoke(Unknown Source)
at org.testng.internal.MethodInvocationHelper.invokeMethod(MethodInvocationHelper.java:124)
at org.testng.internal.Invoker.invokeMethod(Invoker.java:583)
at org.testng.internal.Invoker.retryFailed(Invoker.java:839)
at org.testng.internal.Invoker.invokeTestMethods(Invoker.java:1010)
at org.testng.internal.TestMethodWorker.invokeTestMethods(TestMethodWorker.java:125)
at org.testng.internal.TestMethodWorker.run(TestMethodWorker.java:109)
at org.testng.TestRunner.privateRun(TestRunner.java:648)
at org.testng.TestRunner.run(TestRunner.java:505)
at org.testng.SuiteRunner.runTest(SuiteRunner.java:455)
at org.testng.SuiteRunner.access$000(SuiteRunner.java:40)
at org.testng.SuiteRunner$SuiteWorker.run(SuiteRunner.java:489)
at org.testng.internal.thread.ThreadUtil$1.call(ThreadUtil.java:52)
at java.util.concurrent.FutureTask.run(Unknown Source)
at java.util.concurrent.ThreadPoolExecutor.runWorker(Unknown Source)
at java.util.concurrent.ThreadPoolExecutor$Worker.run(Unknown Source)
at java.lang.Thread.run(Unknown Source)
]]>
    </failure>
  </testcase> <!-- test2 -->
  <testcase name="test2" time="0.005" classname="org.Failed.Testcase1">
    <skipped/>
  </testcase> <!-- test2 -->
  <testcase name="hardAssert" time="0.020" classname="org.Failed.Testcase1"/>
</testsuite> <!-- org.Failed.Testcase1 -->
